<?xml version="1.0" ?>
<!-- =================================================================================== -->
<!-- |    This document was autogenerated by xacro from hero.xacro                     | -->
<!-- |    EDITING THIS FILE BY HAND IS NOT RECOMMENDED                                 | -->
<!-- =================================================================================== -->
<robot>
  <!-- Here was the base link definitions -->
  <link name="base_link">
    <visual>
      <origin rpy="0 0 1.5707963267948966" xyz="0 0 0"/>
      <geometry>
        <mesh filename="package://hero_description/meshes/base_link.obj" scale="1 1 1"/>
      </geometry>
    </visual>
    <collision>
      <origin rpy="0 0 1.5707963267948966" xyz="0 0 0.0121"/>
      <geometry>
        <!-- <cylinde size="0.068 0.068 0.048"/> -->
        <cylinder length="0.042" radius="0.037"/>
        <!-- <mesh filename="package://hero_description/meshes/base_link.dae" scale="1 1 1"/> -->
      </geometry>
    </collision>
    <inertial>
      <mass value="0.090"/>
      <origin rpy="1.5707963267948966 0 0" xyz="0 0.0002 0"/>
      <inertia ixx="5.9250000000000004e-05" ixy="0" ixz="0" iyy="5.9250000000000004e-05" iyz="0" izz="5.5125000000000005e-05"/>
      <!-- <inertia ixx="0.1" ixy = "0" ixz = "0" iyy="0.1" iyz = "0" izz="0.1" /> -->
    </inertial>
  </link>
  <gazebo reference="base_link">
    <gravity>1</gravity>
    <mu1 value="0.01"/>
    <mu2 value="0.01"/>
    <!-- <maxVel value="0.10"/>  -->
    <maxContacts>4</maxContacts>
    <selfCollide>1</selfCollide>
  </gazebo>
  <!--  Here was the hat joint and link -->
  <joint name="hat_joint" type="fixed">
    <origin rpy="0 0 0" xyz="-0.00245 -0.00216 0.06027"/>
    <parent link="base_link"/>
    <child link="hat_link"/>
  </joint>
  <link name="hat_link">
    <visual>
      <origin rpy="0 0 0" xyz="0 0 0"/>
      <geometry>
        <mesh filename="package://hero_description/meshes/hat.obj" scale="1 1 1"/>
      </geometry>
    </visual>
    <collision>
      <origin rpy="0 0 0" xyz="0 0 0"/>
      <geometry>
        <!-- <box size="0.068 0.068 0.02"/> -->
        <!-- <cylinder length="0.02" radius="0.040"/> -->
        <mesh filename="package://hero_description/meshes/hat.obj" scale="1 1 1"/>
      </geometry>
    </collision>
    <inertial>
      <mass value="0.010"/>
      <origin rpy="0 0 0" xyz="0 0 0"/>
      <inertia ixx="3.395833333333334e-06" ixy="0" ixz="0" iyy="3.395833333333334e-06" iyz="0" izz="6.1250000000000015e-06"/>
      <!-- <inertia ixx="0.1" ixy = "0" ixz = "0" iyy="0.1" iyz = "0" izz="0.1" /> -->
    </inertial>
  </link>
  <gazebo reference="hat_link">
    <gravity>1</gravity>
    <!-- <mu1 value="0.005"/>
    <mu2 value="0.005"/> -->
    <maxVel value="0.10"/>
    <maxContacts>0</maxContacts>
    <selfCollide>0</selfCollide>
  </gazebo>
  <!--  Here was the left wheel joint and link -->
  <joint name="left_wheel_joint" type="continuous">
    <parent link="base_link"/>
    <child link="left_wheel_link"/>
    <origin rpy="0 0 0" xyz="0.0 0.0323 0.01548"/>
    <axis xyz="0 1 0"/>
    <limit effort="0.1" velocity="0.3"/>
    <dynamics damping="0.0001" friction="0.0"/>
  </joint>
  <link name="left_wheel_link">
    <visual>
      <origin rpy="0 0 0" xyz="0 0 0.0"/>
      <geometry>
        <mesh filename="package://hero_description/meshes/wheel.obj" scale="1 1 1"/>
      </geometry>
    </visual>
    <collision>
      <origin rpy="1.5707963267948966 0 0" xyz="0 0 0.0"/>
      <geometry>
        <cylinder length="0.008" radius="0.025"/>
      </geometry>
    </collision>
    <inertial>
      <mass value="0.020"/>
      <origin rpy="1.5707963267948966 0 0" xyz="0 0 0"/>
      <inertia ixx="1.6158333333333339e-06" ixy="0" ixz="0" iyy="1.6158333333333339e-06" iyz="0" izz="3.125e-06"/>
      <!-- <inertia ixx="0.1" ixy = "0" ixz = "0" iyy="0.1" iyz = "0" izz="0.1" /> -->
    </inertial>
  </link>
  <gazebo reference="left_wheel_link">
    <mu1 value="1.0"/>
    <mu2 value="1.0"/>
    <!-- <maxVel value="0.10"/>  -->
    <!-- <kp value="10000000.0"/>
    <kd value="1.0"/>
    <fdir1 value="1 0 0"/> -->
    <gravity>1</gravity>
    <maxContacts>4</maxContacts>
    <selfCollide>0</selfCollide>
  </gazebo>
  <!--  Here was the right wheel joint and link -->
  <joint name="right_wheel_joint" type="continuous">
    <axis xyz="0 1 0"/>
    <limit effort="0.1" velocity="0.3"/>
    <dynamics damping="0.0001" friction="0"/>
    <origin rpy="0 0 0" xyz="0.0 -0.0323 0.01548"/>
    <parent link="base_link"/>
    <child link="right_wheel_link"/>
  </joint>
  <link name="right_wheel_link">
    <visual>
      <origin rpy="-3.141592653589793 0 0" xyz="0 0 0.0"/>
      <geometry>
        <mesh filename="package://hero_description/meshes/wheel.obj" scale="1 1 1"/>
      </geometry>
    </visual>
    <collision>
      <origin rpy="-1.5707963267948966 0 0" xyz="0 0 0.0"/>
      <geometry>
        <cylinder length="0.008" radius="0.025"/>
      </geometry>
    </collision>
    <inertial>
      <mass value="0.020"/>
      <origin rpy="-1.5707963267948966 0 0" xyz="0 0 0"/>
      <inertia ixx="1.6158333333333339e-06" ixy="0" ixz="0" iyy="1.6158333333333339e-06" iyz="0" izz="3.125e-06"/>
      <!-- <inertia ixx="0.1" ixy = "0" ixz = "0" iyy="0.1" iyz = "0" izz="0.1" /> -->
    </inertial>
  </link>
  <gazebo reference="right_wheel_link">
    <mu1 value="1.0"/>
    <mu2 value="1.0"/>
    <!-- <maxVel value="0.10"/>  -->
    <!-- <kp value="10000000.0"/>
    <kd value="1.0"/>
    <fdir1 value="1 0 0"/> -->
    <gravity>1</gravity>
    <maxContacts>4</maxContacts>
    <selfCollide>0</selfCollide>
  </gazebo>
</robot>

